<sdf version='1.7'>
  <model name='robile3_config'>
    <link name='base_link'>
      <inertial>
        <pose>0.015691 9.6e-05 0.171122 0 -0 0</pose>
        <mass>31.1</mass>
        <inertia>
          <ixx>0.692584</ixx>
          <ixy>4.5574e-05</ixy>
          <ixz>-0.0273444</ixz>
          <iyy>1.56699</iyy>
          <iyz>6.36656e-06</iyz>
          <izz>1.9621</izz>
        </inertia>
      </inertial>
      <collision name='base_link_fixed_joint_lump__base_laser_mount_collision'>
        <pose>0.4 0 0.08 0 -0 1.57079</pose>
        <geometry>
          <box>
            <size>0.1 0.108 0.117</size>
          </box>
        </geometry>
      </collision>
      <collision name='base_link_fixed_joint_lump__base_laser_collision_1'>
        <pose>0.43 0 0.179 0 -0 0</pose>
        <geometry>
          <box>
            <size>0.105 0.1 0.1</size>
          </box>
        </geometry>
        <surface>
          <contact>
            <ode/>
          </contact>
          <friction>
            <ode/>
          </friction>
        </surface>
      </collision>
      <collision name='base_link_fixed_joint_lump__robile_1_link_collision_2'>
        <pose>0.2335 0.1166 0.169 0 -0 0</pose>
        <geometry>
          <box>
            <size>0.233 0.233 0.239</size>
          </box>
        </geometry>
      </collision>
      <collision name='base_link_fixed_joint_lump__robile_2_link_collision_3'>
        <pose>0.2335 -0.1164 0.169 0 -0 0</pose>
        <geometry>
          <box>
            <size>0.233 0.233 0.239</size>
          </box>
        </geometry>
      </collision>
      <collision name='base_link_fixed_joint_lump__robile_3_link_collision_4'>
        <pose>0.0005 0.1166 0.169 0 -0 0</pose>
        <geometry>
          <box>
            <size>0.233 0.233 0.239</size>
          </box>
        </geometry>
      </collision>
      <collision name='base_link_fixed_joint_lump__robile_4_link_collision_5'>
        <pose>0.0005 -0.1164 0.169 0 -0 0</pose>
        <geometry>
          <box>
            <size>0.233 0.233 0.239</size>
          </box>
        </geometry>
      </collision>
      <collision name='base_link_fixed_joint_lump__robile_5_link_collision_6'>
        <pose>-0.2325 0.1166 0.169 0 -0 0</pose>
        <geometry>
          <box>
            <size>0.233 0.233 0.239</size>
          </box>
        </geometry>
      </collision>
      <collision name='base_link_fixed_joint_lump__robile_6_link_collision_7'>
        <pose>-0.2325 -0.1164 0.169 0 -0 0</pose>
        <geometry>
          <box>
            <size>0.233 0.233 0.239</size>
          </box>
        </geometry>
      </collision>
      <visual name='base_link_fixed_joint_lump__base_laser_mount_visual'>
        <pose>0.4 0 0.08 0 -0 1.57079</pose>
        <geometry>
          <mesh>
            <scale>1 1 1</scale>
            <uri>model://robile_description/meshes/sensors/lms1xx_mount.dae</uri>
          </mesh>
        </geometry>
      </visual>
      <visual name='base_link_fixed_joint_lump__base_laser_visual_1'>
        <pose>0.43 0 0.229 0 -0 0</pose>
        <geometry>
          <mesh>
            <scale>1 1 1</scale>
            <uri>model://robile_description/meshes/sensors/sick-lms1xx.dae</uri>
          </mesh>
        </geometry>
      </visual>
      <visual name='base_link_fixed_joint_lump__robile_1_link_visual_2'>
        <pose>0.233 0.1165 0.05 0 -0 0</pose>
        <geometry>
          <mesh>
            <scale>1 1 1</scale>
            <uri>file:///home/jobe/ros2_ws/install/robile_description/share/robile_description/meshes/robile_brick_housing/wheeled_brick_housing.dae</uri>
          </mesh>
        </geometry>
      </visual>
      <visual name='base_link_fixed_joint_lump__robile_1_link_visual_3'>
        <pose>0.233 0.1165 0.05 0 -0 0</pose>
        <geometry>
          <mesh>
            <scale>1 1 1</scale>
            <uri>file:///home/jobe/ros2_ws/install/robile_description/share/robile_description/meshes/robile_brick_housing/lid.dae</uri>
          </mesh>
        </geometry>
      </visual>
      <visual name='base_link_fixed_joint_lump__robile_1_link_visual_4'>
        <pose>0.233 0.1165 0.05 0 -0 0</pose>
        <geometry>
          <mesh>
            <scale>1 1 1</scale>
            <uri>file:///home/jobe/ros2_ws/install/robile_description/share/robile_description/meshes/robile_brick_housing/lid_cover_red.dae</uri>
          </mesh>
        </geometry>
      </visual>
      <visual name='base_link_fixed_joint_lump__robile_2_link_visual_5'>
        <pose>0.233 -0.1165 0.05 0 -0 0</pose>
        <geometry>
          <mesh>
            <scale>1 1 1</scale>
            <uri>file:///home/jobe/ros2_ws/install/robile_description/share/robile_description/meshes/robile_brick_housing/wheeled_brick_housing.dae</uri>
          </mesh>
        </geometry>
      </visual>
      <visual name='base_link_fixed_joint_lump__robile_2_link_visual_6'>
        <pose>0.233 -0.1165 0.05 0 -0 0</pose>
        <geometry>
          <mesh>
            <scale>1 1 1</scale>
            <uri>file:///home/jobe/ros2_ws/install/robile_description/share/robile_description/meshes/robile_brick_housing/lid.dae</uri>
          </mesh>
        </geometry>
      </visual>
      <visual name='base_link_fixed_joint_lump__robile_2_link_visual_7'>
        <pose>0.233 -0.1165 0.05 0 -0 0</pose>
        <geometry>
          <mesh>
            <scale>1 1 1</scale>
            <uri>file:///home/jobe/ros2_ws/install/robile_description/share/robile_description/meshes/robile_brick_housing/lid_cover_red.dae</uri>
          </mesh>
        </geometry>
      </visual>
      <visual name='base_link_fixed_joint_lump__robile_3_link_visual_8'>
        <pose>0 0.1165 0.05 0 -0 0</pose>
        <geometry>
          <mesh>
            <scale>1 1 1</scale>
            <uri>file:///home/jobe/ros2_ws/install/robile_description/share/robile_description/meshes/robile_brick_housing/general_brick_housing.dae</uri>
          </mesh>
        </geometry>
      </visual>
      <visual name='base_link_fixed_joint_lump__robile_3_link_visual_9'>
        <pose>0 0.1165 0.05 0 -0 0</pose>
        <geometry>
          <mesh>
            <scale>1 1 1</scale>
            <uri>file:///home/jobe/ros2_ws/install/robile_description/share/robile_description/meshes/robile_brick_housing/lid.dae</uri>
          </mesh>
        </geometry>
      </visual>
      <visual name='base_link_fixed_joint_lump__robile_3_link_visual_10'>
        <pose>0 0.1165 0.05 0 -0 0</pose>
        <geometry>
          <mesh>
            <scale>1 1 1</scale>
            <uri>file:///home/jobe/ros2_ws/install/robile_description/share/robile_description/meshes/robile_brick_housing/lid_cover_yellow.dae</uri>
          </mesh>
        </geometry>
      </visual>
      <visual name='base_link_fixed_joint_lump__robile_4_link_visual_11'>
        <pose>0 -0.1165 0.05 0 -0 0</pose>
        <geometry>
          <mesh>
            <scale>1 1 1</scale>
            <uri>file:///home/jobe/ros2_ws/install/robile_description/share/robile_description/meshes/robile_brick_housing/general_brick_housing.dae</uri>
          </mesh>
        </geometry>
      </visual>
      <visual name='base_link_fixed_joint_lump__robile_4_link_visual_12'>
        <pose>0 -0.1165 0.05 0 -0 0</pose>
        <geometry>
          <mesh>
            <scale>1 1 1</scale>
            <uri>file:///home/jobe/ros2_ws/install/robile_description/share/robile_description/meshes/robile_brick_housing/lid.dae</uri>
          </mesh>
        </geometry>
      </visual>
      <visual name='base_link_fixed_joint_lump__robile_4_link_visual_13'>
        <pose>0 -0.1165 0.05 0 -0 0</pose>
        <geometry>
          <mesh>
            <scale>1 1 1</scale>
            <uri>file:///home/jobe/ros2_ws/install/robile_description/share/robile_description/meshes/robile_brick_housing/lid_cover_green.dae</uri>
          </mesh>
        </geometry>
      </visual>
      <visual name='base_link_fixed_joint_lump__robile_5_link_visual_14'>
        <pose>-0.233 0.1165 0.05 0 -0 0</pose>
        <geometry>
          <mesh>
            <scale>1 1 1</scale>
            <uri>file:///home/jobe/ros2_ws/install/robile_description/share/robile_description/meshes/robile_brick_housing/wheeled_brick_housing.dae</uri>
          </mesh>
        </geometry>
      </visual>
      <visual name='base_link_fixed_joint_lump__robile_5_link_visual_15'>
        <pose>-0.233 0.1165 0.05 0 -0 0</pose>
        <geometry>
          <mesh>
            <scale>1 1 1</scale>
            <uri>file:///home/jobe/ros2_ws/install/robile_description/share/robile_description/meshes/robile_brick_housing/lid.dae</uri>
          </mesh>
        </geometry>
      </visual>
      <visual name='base_link_fixed_joint_lump__robile_5_link_visual_16'>
        <pose>-0.233 0.1165 0.05 0 -0 0</pose>
        <geometry>
          <mesh>
            <scale>1 1 1</scale>
            <uri>file:///home/jobe/ros2_ws/install/robile_description/share/robile_description/meshes/robile_brick_housing/lid_cover_red.dae</uri>
          </mesh>
        </geometry>
      </visual>
      <visual name='base_link_fixed_joint_lump__robile_6_link_visual_17'>
        <pose>-0.233 -0.1165 0.05 0 -0 0</pose>
        <geometry>
          <mesh>
            <scale>1 1 1</scale>
            <uri>file:///home/jobe/ros2_ws/install/robile_description/share/robile_description/meshes/robile_brick_housing/wheeled_brick_housing.dae</uri>
          </mesh>
        </geometry>
      </visual>
      <visual name='base_link_fixed_joint_lump__robile_6_link_visual_18'>
        <pose>-0.233 -0.1165 0.05 0 -0 0</pose>
        <geometry>
          <mesh>
            <scale>1 1 1</scale>
            <uri>file:///home/jobe/ros2_ws/install/robile_description/share/robile_description/meshes/robile_brick_housing/lid.dae</uri>
          </mesh>
        </geometry>
      </visual>
      <visual name='base_link_fixed_joint_lump__robile_6_link_visual_19'>
        <pose>-0.233 -0.1165 0.05 0 -0 0</pose>
        <geometry>
          <mesh>
            <scale>1 1 1</scale>
            <uri>file:///home/jobe/ros2_ws/install/robile_description/share/robile_description/meshes/robile_brick_housing/lid_cover_red.dae</uri>
          </mesh>
        </geometry>
      </visual>
      <gravity>0</gravity>
      <sensor name='base_laser' type='ray'>
        <visualize>0</visualize>
        <update_rate>50</update_rate>
        <ray>
          <scan>
            <horizontal>
              <samples>720</samples>
              <resolution>1</resolution>
              <min_angle>-2.35619</min_angle>
              <max_angle>2.35619</max_angle>
            </horizontal>
          </scan>
          <range>
            <min>0.1</min>
            <max>30</max>
            <resolution>0.01</resolution>
          </range>
          <noise>
            <type>gaussian</type>
            <mean>0</mean>
            <stddev>0.01</stddev>
          </noise>
        </ray>
        <plugin name='gazebo_ros_laser' filename='libgazebo_ros_ray_sensor.so'>
          <ros>
            <remapping>~/out:=scan</remapping>
          </ros>
          <output_type>sensor_msgs/LaserScan</output_type>
        </plugin>
        <pose>0.43 0 0.229 0 -0 0</pose>
      </sensor>
    </link>
    <joint name='robile_1_drive_pivot_joint' type='revolute'>
      <pose relative_to='base_link'>0.233 0.1165 0.05 0 -0 0</pose>
      <parent>base_link</parent>
      <child>robile_1_drive_pivot_link</child>
      <axis>
        <xyz>0 0 1</xyz>
        <limit>
          <lower>-1e+16</lower>
          <upper>1e+16</upper>
        </limit>
        <dynamics>
          <spring_reference>0</spring_reference>
          <spring_stiffness>0</spring_stiffness>
        </dynamics>
      </axis>
    </joint>
    <link name='robile_1_drive_pivot_link'>
      <pose relative_to='robile_1_drive_pivot_joint'>0 0 0 0 -0 0</pose>
      <inertial>
        <pose>0 0 0 0 -0 0</pose>
        <mass>10</mass>
        <inertia>
          <ixx>0.0904817</ixx>
          <ixy>0</ixy>
          <ixz>0</ixz>
          <iyy>0.0904817</iyy>
          <iyz>0</iyz>
          <izz>0.0904817</izz>
        </inertia>
      </inertial>
      <collision name='robile_1_drive_pivot_link_collision'>
        <pose>0 0 0.07 0 -0 0</pose>
        <geometry>
          <box>
            <size>0.105 0.154 0.025</size>
          </box>
        </geometry>
      </collision>
      <visual name='robile_1_drive_pivot_link_visual'>
        <pose>0 0 0 0 -0 0</pose>
        <geometry>
          <mesh>
            <scale>1 1 1</scale>
            <uri>file:///home/jobe/ros2_ws/install/robile_description/share/robile_description/meshes/kelo_drive/kelo_drive_base.dae</uri>
          </mesh>
        </geometry>
      </visual>
    </link>
    <joint name='robile_1_drive_left_hub_wheel_joint' type='revolute'>
      <pose relative_to='robile_1_drive_pivot_link'>-0.01 0.039326 0.001514 0 -0 0</pose>
      <parent>robile_1_drive_pivot_link</parent>
      <child>robile_1_drive_left_hub_wheel_link</child>
      <axis>
        <xyz>0 1 0</xyz>
        <limit>
          <lower>-1e+16</lower>
          <upper>1e+16</upper>
        </limit>
        <dynamics>
          <spring_reference>0</spring_reference>
          <spring_stiffness>0</spring_stiffness>
        </dynamics>
      </axis>
    </joint>
    <link name='robile_1_drive_left_hub_wheel_link'>
      <pose relative_to='robile_1_drive_left_hub_wheel_joint'>0 0 0 0 -0 0</pose>
      <inertial>
        <pose>0 0 0 0 -0 0</pose>
        <mass>10</mass>
        <inertia>
          <ixx>0.0904817</ixx>
          <ixy>0</ixy>
          <ixz>0</ixz>
          <iyy>0.0904817</iyy>
          <iyz>0</iyz>
          <izz>0.0904817</izz>
        </inertia>
      </inertial>
      <collision name='robile_1_drive_left_hub_wheel_link_collision'>
        <pose>0 0 0 1.5708 -0 0</pose>
        <geometry>
          <cylinder>
            <length>0.035</length>
            <radius>0.0515</radius>
          </cylinder>
        </geometry>
      </collision>
      <visual name='robile_1_drive_left_hub_wheel_link_visual'>
        <pose>0 0 0 0 -0 0</pose>
        <geometry>
          <mesh>
            <scale>1 1 1</scale>
            <uri>file:///home/jobe/ros2_ws/install/robile_description/share/robile_description/meshes/kelo_drive/kelo_drive_wheel.dae</uri>
          </mesh>
        </geometry>
      </visual>
    </link>
    <joint name='robile_1_drive_right_hub_wheel_joint' type='revolute'>
      <pose relative_to='robile_1_drive_pivot_link'>-0.01 -0.039326 0.001514 0 -0 0</pose>
      <parent>robile_1_drive_pivot_link</parent>
      <child>robile_1_drive_right_hub_wheel_link</child>
      <axis>
        <xyz>0 1 0</xyz>
        <limit>
          <lower>-1e+16</lower>
          <upper>1e+16</upper>
        </limit>
        <dynamics>
          <spring_reference>0</spring_reference>
          <spring_stiffness>0</spring_stiffness>
        </dynamics>
      </axis>
    </joint>
    <link name='robile_1_drive_right_hub_wheel_link'>
      <pose relative_to='robile_1_drive_right_hub_wheel_joint'>0 0 0 0 -0 0</pose>
      <inertial>
        <pose>0 0 0 0 -0 0</pose>
        <mass>10</mass>
        <inertia>
          <ixx>0.0904817</ixx>
          <ixy>0</ixy>
          <ixz>0</ixz>
          <iyy>0.0904817</iyy>
          <iyz>0</iyz>
          <izz>0.0904817</izz>
        </inertia>
      </inertial>
      <collision name='robile_1_drive_right_hub_wheel_link_collision'>
        <pose>0 0 0 1.5708 -0 0</pose>
        <geometry>
          <cylinder>
            <length>0.035</length>
            <radius>0.0515</radius>
          </cylinder>
        </geometry>
      </collision>
      <visual name='robile_1_drive_right_hub_wheel_link_visual'>
        <pose>0 0 0 0 -0 0</pose>
        <geometry>
          <mesh>
            <scale>1 1 1</scale>
            <uri>file:///home/jobe/ros2_ws/install/robile_description/share/robile_description/meshes/kelo_drive/kelo_drive_wheel.dae</uri>
          </mesh>
        </geometry>
      </visual>
    </link>
    <joint name='robile_2_drive_pivot_joint' type='revolute'>
      <pose relative_to='base_link'>0.233 -0.1165 0.05 0 -0 0</pose>
      <parent>base_link</parent>
      <child>robile_2_drive_pivot_link</child>
      <axis>
        <xyz>0 0 1</xyz>
        <limit>
          <lower>-1e+16</lower>
          <upper>1e+16</upper>
        </limit>
        <dynamics>
          <spring_reference>0</spring_reference>
          <spring_stiffness>0</spring_stiffness>
        </dynamics>
      </axis>
    </joint>
    <link name='robile_2_drive_pivot_link'>
      <pose relative_to='robile_2_drive_pivot_joint'>0 0 0 0 -0 0</pose>
      <inertial>
        <pose>0 0 0 0 -0 0</pose>
        <mass>10</mass>
        <inertia>
          <ixx>0.0904817</ixx>
          <ixy>0</ixy>
          <ixz>0</ixz>
          <iyy>0.0904817</iyy>
          <iyz>0</iyz>
          <izz>0.0904817</izz>
        </inertia>
      </inertial>
      <collision name='robile_2_drive_pivot_link_collision'>
        <pose>0 0 0.07 0 -0 0</pose>
        <geometry>
          <box>
            <size>0.105 0.154 0.025</size>
          </box>
        </geometry>
      </collision>
      <visual name='robile_2_drive_pivot_link_visual'>
        <pose>0 0 0 0 -0 0</pose>
        <geometry>
          <mesh>
            <scale>1 1 1</scale>
            <uri>file:///home/jobe/ros2_ws/install/robile_description/share/robile_description/meshes/kelo_drive/kelo_drive_base.dae</uri>
          </mesh>
        </geometry>
      </visual>
    </link>
    <joint name='robile_2_drive_left_hub_wheel_joint' type='revolute'>
      <pose relative_to='robile_2_drive_pivot_link'>-0.01 0.039326 0.001514 0 -0 0</pose>
      <parent>robile_2_drive_pivot_link</parent>
      <child>robile_2_drive_left_hub_wheel_link</child>
      <axis>
        <xyz>0 1 0</xyz>
        <limit>
          <lower>-1e+16</lower>
          <upper>1e+16</upper>
        </limit>
        <dynamics>
          <spring_reference>0</spring_reference>
          <spring_stiffness>0</spring_stiffness>
        </dynamics>
      </axis>
    </joint>
    <link name='robile_2_drive_left_hub_wheel_link'>
      <pose relative_to='robile_2_drive_left_hub_wheel_joint'>0 0 0 0 -0 0</pose>
      <inertial>
        <pose>0 0 0 0 -0 0</pose>
        <mass>10</mass>
        <inertia>
          <ixx>0.0904817</ixx>
          <ixy>0</ixy>
          <ixz>0</ixz>
          <iyy>0.0904817</iyy>
          <iyz>0</iyz>
          <izz>0.0904817</izz>
        </inertia>
      </inertial>
      <collision name='robile_2_drive_left_hub_wheel_link_collision'>
        <pose>0 0 0 1.5708 -0 0</pose>
        <geometry>
          <cylinder>
            <length>0.035</length>
            <radius>0.0515</radius>
          </cylinder>
        </geometry>
      </collision>
      <visual name='robile_2_drive_left_hub_wheel_link_visual'>
        <pose>0 0 0 0 -0 0</pose>
        <geometry>
          <mesh>
            <scale>1 1 1</scale>
            <uri>file:///home/jobe/ros2_ws/install/robile_description/share/robile_description/meshes/kelo_drive/kelo_drive_wheel.dae</uri>
          </mesh>
        </geometry>
      </visual>
    </link>
    <joint name='robile_2_drive_right_hub_wheel_joint' type='revolute'>
      <pose relative_to='robile_2_drive_pivot_link'>-0.01 -0.039326 0.001514 0 -0 0</pose>
      <parent>robile_2_drive_pivot_link</parent>
      <child>robile_2_drive_right_hub_wheel_link</child>
      <axis>
        <xyz>0 1 0</xyz>
        <limit>
          <lower>-1e+16</lower>
          <upper>1e+16</upper>
        </limit>
        <dynamics>
          <spring_reference>0</spring_reference>
          <spring_stiffness>0</spring_stiffness>
        </dynamics>
      </axis>
    </joint>
    <link name='robile_2_drive_right_hub_wheel_link'>
      <pose relative_to='robile_2_drive_right_hub_wheel_joint'>0 0 0 0 -0 0</pose>
      <inertial>
        <pose>0 0 0 0 -0 0</pose>
        <mass>10</mass>
        <inertia>
          <ixx>0.0904817</ixx>
          <ixy>0</ixy>
          <ixz>0</ixz>
          <iyy>0.0904817</iyy>
          <iyz>0</iyz>
          <izz>0.0904817</izz>
        </inertia>
      </inertial>
      <collision name='robile_2_drive_right_hub_wheel_link_collision'>
        <pose>0 0 0 1.5708 -0 0</pose>
        <geometry>
          <cylinder>
            <length>0.035</length>
            <radius>0.0515</radius>
          </cylinder>
        </geometry>
      </collision>
      <visual name='robile_2_drive_right_hub_wheel_link_visual'>
        <pose>0 0 0 0 -0 0</pose>
        <geometry>
          <mesh>
            <scale>1 1 1</scale>
            <uri>file:///home/jobe/ros2_ws/install/robile_description/share/robile_description/meshes/kelo_drive/kelo_drive_wheel.dae</uri>
          </mesh>
        </geometry>
      </visual>
    </link>
    <joint name='robile_5_drive_pivot_joint' type='revolute'>
      <pose relative_to='base_link'>-0.233 0.1165 0.05 0 -0 0</pose>
      <parent>base_link</parent>
      <child>robile_5_drive_pivot_link</child>
      <axis>
        <xyz>0 0 1</xyz>
        <limit>
          <lower>-1e+16</lower>
          <upper>1e+16</upper>
        </limit>
        <dynamics>
          <spring_reference>0</spring_reference>
          <spring_stiffness>0</spring_stiffness>
        </dynamics>
      </axis>
    </joint>
    <link name='robile_5_drive_pivot_link'>
      <pose relative_to='robile_5_drive_pivot_joint'>0 0 0 0 -0 0</pose>
      <inertial>
        <pose>0 0 0 0 -0 0</pose>
        <mass>10</mass>
        <inertia>
          <ixx>0.0904817</ixx>
          <ixy>0</ixy>
          <ixz>0</ixz>
          <iyy>0.0904817</iyy>
          <iyz>0</iyz>
          <izz>0.0904817</izz>
        </inertia>
      </inertial>
      <collision name='robile_5_drive_pivot_link_collision'>
        <pose>0 0 0.07 0 -0 0</pose>
        <geometry>
          <box>
            <size>0.105 0.154 0.025</size>
          </box>
        </geometry>
      </collision>
      <visual name='robile_5_drive_pivot_link_visual'>
        <pose>0 0 0 0 -0 0</pose>
        <geometry>
          <mesh>
            <scale>1 1 1</scale>
            <uri>file:///home/jobe/ros2_ws/install/robile_description/share/robile_description/meshes/kelo_drive/kelo_drive_base.dae</uri>
          </mesh>
        </geometry>
      </visual>
    </link>
    <joint name='robile_5_drive_left_hub_wheel_joint' type='revolute'>
      <pose relative_to='robile_5_drive_pivot_link'>-0.01 0.039326 0.001514 0 -0 0</pose>
      <parent>robile_5_drive_pivot_link</parent>
      <child>robile_5_drive_left_hub_wheel_link</child>
      <axis>
        <xyz>0 1 0</xyz>
        <limit>
          <lower>-1e+16</lower>
          <upper>1e+16</upper>
        </limit>
        <dynamics>
          <spring_reference>0</spring_reference>
          <spring_stiffness>0</spring_stiffness>
        </dynamics>
      </axis>
    </joint>
    <link name='robile_5_drive_left_hub_wheel_link'>
      <pose relative_to='robile_5_drive_left_hub_wheel_joint'>0 0 0 0 -0 0</pose>
      <inertial>
        <pose>0 0 0 0 -0 0</pose>
        <mass>10</mass>
        <inertia>
          <ixx>0.0904817</ixx>
          <ixy>0</ixy>
          <ixz>0</ixz>
          <iyy>0.0904817</iyy>
          <iyz>0</iyz>
          <izz>0.0904817</izz>
        </inertia>
      </inertial>
      <collision name='robile_5_drive_left_hub_wheel_link_collision'>
        <pose>0 0 0 1.5708 -0 0</pose>
        <geometry>
          <cylinder>
            <length>0.035</length>
            <radius>0.0515</radius>
          </cylinder>
        </geometry>
      </collision>
      <visual name='robile_5_drive_left_hub_wheel_link_visual'>
        <pose>0 0 0 0 -0 0</pose>
        <geometry>
          <mesh>
            <scale>1 1 1</scale>
            <uri>file:///home/jobe/ros2_ws/install/robile_description/share/robile_description/meshes/kelo_drive/kelo_drive_wheel.dae</uri>
          </mesh>
        </geometry>
      </visual>
    </link>
    <joint name='robile_5_drive_right_hub_wheel_joint' type='revolute'>
      <pose relative_to='robile_5_drive_pivot_link'>-0.01 -0.039326 0.001514 0 -0 0</pose>
      <parent>robile_5_drive_pivot_link</parent>
      <child>robile_5_drive_right_hub_wheel_link</child>
      <axis>
        <xyz>0 1 0</xyz>
        <limit>
          <lower>-1e+16</lower>
          <upper>1e+16</upper>
        </limit>
        <dynamics>
          <spring_reference>0</spring_reference>
          <spring_stiffness>0</spring_stiffness>
        </dynamics>
      </axis>
    </joint>
    <link name='robile_5_drive_right_hub_wheel_link'>
      <pose relative_to='robile_5_drive_right_hub_wheel_joint'>0 0 0 0 -0 0</pose>
      <inertial>
        <pose>0 0 0 0 -0 0</pose>
        <mass>10</mass>
        <inertia>
          <ixx>0.0904817</ixx>
          <ixy>0</ixy>
          <ixz>0</ixz>
          <iyy>0.0904817</iyy>
          <iyz>0</iyz>
          <izz>0.0904817</izz>
        </inertia>
      </inertial>
      <collision name='robile_5_drive_right_hub_wheel_link_collision'>
        <pose>0 0 0 1.5708 -0 0</pose>
        <geometry>
          <cylinder>
            <length>0.035</length>
            <radius>0.0515</radius>
          </cylinder>
        </geometry>
      </collision>
      <visual name='robile_5_drive_right_hub_wheel_link_visual'>
        <pose>0 0 0 0 -0 0</pose>
        <geometry>
          <mesh>
            <scale>1 1 1</scale>
            <uri>file:///home/jobe/ros2_ws/install/robile_description/share/robile_description/meshes/kelo_drive/kelo_drive_wheel.dae</uri>
          </mesh>
        </geometry>
      </visual>
    </link>
    <joint name='robile_6_drive_pivot_joint' type='revolute'>
      <pose relative_to='base_link'>-0.233 -0.1165 0.05 0 -0 0</pose>
      <parent>base_link</parent>
      <child>robile_6_drive_pivot_link</child>
      <axis>
        <xyz>0 0 1</xyz>
        <limit>
          <lower>-1e+16</lower>
          <upper>1e+16</upper>
        </limit>
        <dynamics>
          <spring_reference>0</spring_reference>
          <spring_stiffness>0</spring_stiffness>
        </dynamics>
      </axis>
    </joint>
    <link name='robile_6_drive_pivot_link'>
      <pose relative_to='robile_6_drive_pivot_joint'>0 0 0 0 -0 0</pose>
      <inertial>
        <pose>0 0 0 0 -0 0</pose>
        <mass>10</mass>
        <inertia>
          <ixx>0.0904817</ixx>
          <ixy>0</ixy>
          <ixz>0</ixz>
          <iyy>0.0904817</iyy>
          <iyz>0</iyz>
          <izz>0.0904817</izz>
        </inertia>
      </inertial>
      <collision name='robile_6_drive_pivot_link_collision'>
        <pose>0 0 0.07 0 -0 0</pose>
        <geometry>
          <box>
            <size>0.105 0.154 0.025</size>
          </box>
        </geometry>
      </collision>
      <visual name='robile_6_drive_pivot_link_visual'>
        <pose>0 0 0 0 -0 0</pose>
        <geometry>
          <mesh>
            <scale>1 1 1</scale>
            <uri>file:///home/jobe/ros2_ws/install/robile_description/share/robile_description/meshes/kelo_drive/kelo_drive_base.dae</uri>
          </mesh>
        </geometry>
      </visual>
    </link>
    <joint name='robile_6_drive_left_hub_wheel_joint' type='revolute'>
      <pose relative_to='robile_6_drive_pivot_link'>-0.01 0.039326 0.001514 0 -0 0</pose>
      <parent>robile_6_drive_pivot_link</parent>
      <child>robile_6_drive_left_hub_wheel_link</child>
      <axis>
        <xyz>0 1 0</xyz>
        <limit>
          <lower>-1e+16</lower>
          <upper>1e+16</upper>
        </limit>
        <dynamics>
          <spring_reference>0</spring_reference>
          <spring_stiffness>0</spring_stiffness>
        </dynamics>
      </axis>
    </joint>
    <link name='robile_6_drive_left_hub_wheel_link'>
      <pose relative_to='robile_6_drive_left_hub_wheel_joint'>0 0 0 0 -0 0</pose>
      <inertial>
        <pose>0 0 0 0 -0 0</pose>
        <mass>10</mass>
        <inertia>
          <ixx>0.0904817</ixx>
          <ixy>0</ixy>
          <ixz>0</ixz>
          <iyy>0.0904817</iyy>
          <iyz>0</iyz>
          <izz>0.0904817</izz>
        </inertia>
      </inertial>
      <collision name='robile_6_drive_left_hub_wheel_link_collision'>
        <pose>0 0 0 1.5708 -0 0</pose>
        <geometry>
          <cylinder>
            <length>0.035</length>
            <radius>0.0515</radius>
          </cylinder>
        </geometry>
      </collision>
      <visual name='robile_6_drive_left_hub_wheel_link_visual'>
        <pose>0 0 0 0 -0 0</pose>
        <geometry>
          <mesh>
            <scale>1 1 1</scale>
            <uri>file:///home/jobe/ros2_ws/install/robile_description/share/robile_description/meshes/kelo_drive/kelo_drive_wheel.dae</uri>
          </mesh>
        </geometry>
      </visual>
    </link>
    <joint name='robile_6_drive_right_hub_wheel_joint' type='revolute'>
      <pose relative_to='robile_6_drive_pivot_link'>-0.01 -0.039326 0.001514 0 -0 0</pose>
      <parent>robile_6_drive_pivot_link</parent>
      <child>robile_6_drive_right_hub_wheel_link</child>
      <axis>
        <xyz>0 1 0</xyz>
        <limit>
          <lower>-1e+16</lower>
          <upper>1e+16</upper>
        </limit>
        <dynamics>
          <spring_reference>0</spring_reference>
          <spring_stiffness>0</spring_stiffness>
        </dynamics>
      </axis>
    </joint>
    <link name='robile_6_drive_right_hub_wheel_link'>
      <pose relative_to='robile_6_drive_right_hub_wheel_joint'>0 0 0 0 -0 0</pose>
      <inertial>
        <pose>0 0 0 0 -0 0</pose>
        <mass>10</mass>
        <inertia>
          <ixx>0.0904817</ixx>
          <ixy>0</ixy>
          <ixz>0</ixz>
          <iyy>0.0904817</iyy>
          <iyz>0</iyz>
          <izz>0.0904817</izz>
        </inertia>
      </inertial>
      <collision name='robile_6_drive_right_hub_wheel_link_collision'>
        <pose>0 0 0 1.5708 -0 0</pose>
        <geometry>
          <cylinder>
            <length>0.035</length>
            <radius>0.0515</radius>
          </cylinder>
        </geometry>
      </collision>
      <visual name='robile_6_drive_right_hub_wheel_link_visual'>
        <pose>0 0 0 0 -0 0</pose>
        <geometry>
          <mesh>
            <scale>1 1 1</scale>
            <uri>file:///home/jobe/ros2_ws/install/robile_description/share/robile_description/meshes/kelo_drive/kelo_drive_wheel.dae</uri>
          </mesh>
        </geometry>
      </visual>
    </link>
  </model>
</sdf>
